<?xml version="1.0" ?>
<robot name="hanul">

  <link name="base_link">
    <visual>
      <origin xyz="0 0 0" rpy="0 0 0"/>
      <geometry><mesh filename="assets/base.stl"/></geometry>
      <material name="orange"><color rgba="1.0 0.5 0.0 1.0"/></material>
    </visual>
    <collision>
      <origin xyz="0 0 0" rpy="0 0 0"/>
      <geometry><mesh filename="assets/base.stl"/></geometry>
    </collision>
    <inertial>
      <mass value="10.0"/>
      <inertia ixx="0.1" ixy="0" ixz="0" iyy="0.1" iyz="0" izz="0.1"/>
    </inertial>
  </link>

  <link name="wheel_left_link">
    <visual>
      <geometry><mesh filename="assets/Omni Wheel.stl"/></geometry>
      <material name="grey"><color rgba="0.2 0.2 0.2 1"/></material>
    </visual>
    <collision>
      <geometry><mesh filename="assets/Omni Wheel.stl"/></geometry>
    </collision>
    <inertial>
      <mass value="1.0"/>
      <inertia ixx="0.005" ixy="0" ixz="0" iyy="0.005" iyz="0" izz="0.005"/>
    </inertial>
  </link>

  <joint name="joint_wheel_left" type="continuous">
    <parent link="base_link"/>
    <child link="wheel_left_link"/>
    <origin xyz="0.0664 0.115 0.05" rpy="0 1.5708 -2.0944"/>
    <axis xyz="0 0 1"/>
  </joint>

  <link name="wheel_right_link">
    <visual>
      <geometry><mesh filename="assets/Omni Wheel.stl"/></geometry>
    </visual>
    <collision>
      <geometry><mesh filename="assets/Omni Wheel.stl"/></geometry>
    </collision>
    <inertial>
      <mass value="1.0"/>
      <inertia ixx="0.005" ixy="0" ixz="0" iyy="0.005" iyz="0" izz="0.005"/>
    </inertial>
  </link>

  <joint name="joint_wheel_right" type="continuous">
    <parent link="base_link"/>
    <child link="wheel_right_link"/>
    <origin xyz="0.0664 -0.115 0.05" rpy="0 1.5708 2.0944"/>
    <axis xyz="0 0 1"/>
  </joint>

  <link name="wheel_back_link">
    <visual>
      <geometry><mesh filename="assets/Omni Wheel.stl"/></geometry>
    </visual>
    <collision>
      <geometry><mesh filename="assets/Omni Wheel.stl"/></geometry>
    </collision>
    <inertial>
      <mass value="1.0"/>
      <inertia ixx="0.005" ixy="0" ixz="0" iyy="0.005" iyz="0" izz="0.005"/>
    </inertial>
  </link>

  <joint name="joint_wheel_back" type="continuous">
    <parent link="base_link"/>
    <child link="wheel_back_link"/>
    <origin xyz="-0.1353 0.0 0.05" rpy="0 1.5708 0"/>
    <axis xyz="0 0 1"/>
  </joint>

</robot>
